Workbook

Sheet metadata
A1: image_id | B1: artwork_id | C1: original_file | D1: artist | E1: title | F1: year | G1: genre | H1: medium | I1: label_confidence | J1: photo_quality | K1: include | L1: notes
A2: A001-1 | B2: A001 | C2: Tengiz Mirzashvili"Chubchika".JPG | D2: Tengiz Mirzashvili | E2: Chubchika | G2: landscape | H2: painting | I2: high | J2: ok | K2: yes | L2: village with blossoming trees
A3: A002-1 | B3: A002 | C3: Temur Kadagishvili, "Landscape. Oaks", 2024.JPG | D3: Temur Kadagishvili | E3: Landscape. Oaks | F3: 2024 | G3: landscape | H3: painting | I3: high | J3: ok | K3: yes
A4: A003-1 | B4: A003 | C4: Heather-Dawn SCott , untitled.JPG | D4: Heather-Dawn Scott | E4: Untitled | G4: portrait | H4: painting | I4: low | J4: ok | K4: yes | L4: seated half-length figure
A5: A004-1 | B5: A004 | C5: IMG_8505.JPG | G5: landscape | H5: painting | I5: high | J5: ok | K5: yes | L5: houses on water (cityscape)
A6: A005-1 | B6: A005 | C6: Ushangi Khumarashvili, Abstraction, 2017.JPG | D6: Ushangi Khumarashvili | E6: Abstraction | F6: 2017 | G6: abstract | H6: painting | I6: high | J6: ok | K6: yes
A7: A006-1 | B7: A006 | C7: Ushangi Khumarashvili, Abstraction, 2010.JPG | D7: Ushangi Khumarashvili | E7: Abstraction | F7: 2010 | G7: abstract | H7: painting | I7: high | J7: ok | K7: yes
A8: A007-1 | B8: A007 | C8: IMG_8506.JPG | G8: figurative | H8: painting | I8: high | J8: ok | K8: yes | L8: three children
A9: A008-1 | B9: A008 | C9: Ushangi Khumarashvili, Abstraction.JPG | D9: Ushangi Khumarashvili | E9: Abstraction | G9: abstract | H9: painting | I9: high | J9: ok | K9: yes
A10: A009-1 | B10: A009 | C10: Ushangi Khumarashvili, Abstraction-2.JPG | D10: Ushangi Khumarashvili | E10: Abstraction-2 | G10: abstract | H10: painting | I10: high | J10: ok | K10: yes
A11: A010-1 | B11: A010 | C11: IMG_8507.JPG | G11: figurative | H11: painting | I11: high | J11: ok | K11: yes | L11: single standing figure
A12: A011-1 | B12: A011 | C12: IMG_8508.JPG | G12: landscape | H12: painting | I12: low | J12: ok | K12: yes | L12: village with large crowd; landscape vs figurative
A13: A012-1 | B13: A012 | C13: Ushangi Khumarashvili, "Red Sun", 2013.JPG | D13: Ushangi Khumarashvili | E13: Red Sun | F13: 2013 | G13: abstract | H13: painting | I13: high | J13: ok | K13: yes
A14: A013-1 | B14: A013 | C14: IMG_8509.JPG | G14: figurative | H14: painting | I14: high | J14: ok | K14: yes | L14: group of figures
A15: A014-1 | B15: A014 | C15: George Alexi-Meskhishvili, "Window".JPG | D15: George Alexi-Meskhishvili | E15: Window | G15: abstract | H15: mixed_media | I15: low | J15: reflection | K15: yes | L15: window/glass work
A16: A015-1 | B16: A015 | C16: IMG_8510.JPG | G16: figurative | H16: painting | I16: high | J16: ok | K16: yes | L16: dancers
A17: A016-1 | B17: A016 | C17: Janri Lolashvili, Untitled, 2022.JPG | D17: Janri Lolashvili | E17: Untitled | F17: 2022 | G17: landscape | H17: painting | I17: low | J17: angle | K17: yes | L17: semi-abstract cloudscape
A18: A017-1 | B18: A017 | C18: IMG_8511.JPG | G18: figurative | H18: painting | I18: low | J18: ok | K18: yes | L18: crowd, close to abstract
A19: A018-1 | B19: A018 | C19: Koka Tskhvediani, Untitled.JPG | D19: Koka Tskhvediani | E19: Untitled | G19: abstract | H19: painting | I19: high | J19: glare | K19: yes
A20: A019-1 | B20: A019 | C20: IMG_8512.JPG | G20: landscape | H20: painting | I20: high | J20: ok | K20: yes | L20: village
A21: A020-1 | B21: A020 | C21: Niko TseTskhladze, "Café", 2013.JPG | D21: Niko Tsetskhladze | E21: Cafe | F21: 2013 | G21: figurative | H21: painting | I21: high | J21: ok | K21: yes | L21: bear in a cafe
A22: A021-1 | B22: A021 | C22: IMG_8513.JPG | G22: landscape | H22: painting | I22: high | J22: ok | K22: yes | L22: street with church
A23: A022-1 | B23: A022 | C23: Ushangi Khumarashvili.JPG | D23: Ushangi Khumarashvili | G23: figurative | H23: painting | I23: low | J23: ok | K23: yes | L23: cafe interior, loose brushwork
A24: A023-1 | B24: A023 | C24: IMG_8514.JPG | G24: figurative | H24: painting | I24: high | J24: ok | K24: yes | L24: woman with umbrella
A25: A024-1 | B25: A024 | C25: Temo Japaridze, Untitled.JPG | D25: Temo Japaridze | E25: Untitled | G25: figurative | H25: painting | I25: high | J25: ok | K25: yes | L25: cafe scene
A26: A025-1 | B26: A025 | C26: Levan Chogoshvili, "Aristocracy", 2020.JPG | D26: Levan Chogoshvili | E26: Aristocracy | F26: 2020 | G26: figurative | H26: mixed_media | I26: low | J26: glare | K26: yes | L26: collage with figures
A27: A026-1 | B27: A026 | C27: Merab Tatalashvili, „Shedow café".JPG | D27: Merab Tatalashvili | E27: Shadow Cafe | G27: abstract | H27: painting | I27: low | J27: ok | K27: yes | L27: semi-abstract cafe chairs
A28: A027-1 | B28: A027 | C28: IMG_8515.JPG | G28: landscape | H28: painting | I28: low | J28: ok | K28: yes | L28: Santorini; may be a print
A29: A028-1 | B29: A028 | C29: Koka Tskhvediani, „Cyber Cafe", 2013.JPG | D29: Koka Tskhvediani | E29: Cyber Cafe | F29: 2013 | G29: abstract | H29: painting | I29: low | J29: ok | K29: yes | L29: semi-abstract building facade
A30: A029-1 | B30: A029 | C30: Mzia Lekiashvili "At dawn".JPG | D30: Mzia Lekiashvili | E30: At Dawn | G30: landscape | H30: painting | I30: low | J30: ok | K30: yes | L30: semi-abstract cityscape
A31: A030-1 | B31: A030 | C31: IMG_0799.JPG | G31: portrait | H31: painting | I31: low | J31: ok | K31: yes | L31: seated woman, full figure
A32: A031-1 | B32: A031 | C32: Zurab (Piko) Nizharadze, Musicians.JPG | D32: Zurab (Piko) Nizharadze | E32: Musicians | G32: figurative | H32: painting | I32: high | J32: ok | K32: yes
A33: A032-1 | B33: A032 | C33: Maka Topuridze, "Dancing clowns", 2024.JPG | D33: Maka Topuridze | E33: Dancing Clowns | F33: 2024 | G33: figurative | H33: painting | I33: low | J33: angle | K33: yes | L33: dense semi-abstract figures
A34: A033-1 | B34: A033 | C34: Zurab (Piko) Nizharadze, "Samson and Dalilah".JPG | D34: Zurab (Piko) Nizharadze | E34: Samson and Dalilah | G34: figurative | H34: painting | I34: high | J34: ok | K34: yes
A35: A034-1 | B35: A034 | C35: Oleg Timchenko, Untitled, 2013.JPG | D35: Oleg Timchenko | E35: Untitled | F35: 2013 | G35: figurative | H35: painting | I35: low | J35: ok | K35: yes | L35: two creatures above flowers
A36: A035-1 | B36: A035 | C36: Dea Soselia, "Wine Country", 2023.JPG | D36: Dea Soselia | E36: Wine Country | F36: 2023 | G36: landscape | H36: painting | I36: high | J36: ok | K36: yes
A37: A036-1 | B37: A036 | C37: Zurab Nijaradze -female torso.JPG | D37: Zurab Nizharadze | E37: Female Torso | G37: figurative | H37: painting | I37: high | J37: ok | K37: yes | L37: nude torso
A38: A037-1 | B38: A037 | C38: Murtaz Shvelidze "untitled".JPG | D38: Murtaz Shvelidze | E38: Untitled | F38: 2013 | G38: figurative | H38: painting | I38: high | J38: ok | K38: yes | L38: legs under a table; year from wall label (photo X-038)
A39: X-038 | C39: IMG_0808.JPG | K39: no | L39: wall label only (Murtaz Shvelidze, Untitled, 2013)
A40: A038-1 | B40: A038 | C40: Tengiz Kacheishvili-African Elephant.JPG | D40: Tengiz Kacheishvili | E40: African Elephant | G40: figurative | H40: painting | I40: high | J40: ok | K40: yes | L40: elephant, cubist style
...

Sheet class_counts
A1: Counts are of unique artworks (one row per artwork_id), computed from the metadata sheet.
A3: genre | B3: artworks | C3: high confidence | D3: used in experiments
A4: landscape | B4: =SUMPRODUCT((metadata!$G$2:$G$187="landscape")*(RIGHT(metadata!$A$2:$A$187,2)="-1")) | C4: =SUMPRODUCT((metadata!$G$2:$G$187="landscape")*(metadata!$I$2:$I$187="high")*(RIGHT(metadata!$A$2:$A$187,2)="-1")) | D4: yes
A5: figurative | B5: =SUMPRODUCT((metadata!$G$2:$G$187="figurative")*(RIGHT(metadata!$A$2:$A$187,2)="-1")) | C5: =SUMPRODUCT((metadata!$G$2:$G$187="figurative")*(metadata!$I$2:$I$187="high")*(RIGHT(metadata!$A$2:$A$187,2)="-1")) | D5: yes
A6: abstract | B6: =SUMPRODUCT((metadata!$G$2:$G$187="abstract")*(RIGHT(metadata!$A$2:$A$187,2)="-1")) | C6: =SUMPRODUCT((metadata!$G$2:$G$187="abstract")*(metadata!$I$2:$I$187="high")*(RIGHT(metadata!$A$2:$A$187,2)="-1")) | D6: yes
A7: portrait | B7: =SUMPRODUCT((metadata!$G$2:$G$187="portrait")*(RIGHT(metadata!$A$2:$A$187,2)="-1")) | C7: =SUMPRODUCT((metadata!$G$2:$G$187="portrait")*(metadata!$I$2:$I$187="high")*(RIGHT(metadata!$A$2:$A$187,2)="-1")) | D7: yes
A8: still_life | B8: =SUMPRODUCT((metadata!$G$2:$G$187="still_life")*(RIGHT(metadata!$A$2:$A$187,2)="-1")) | C8: =SUMPRODUCT((metadata!$G$2:$G$187="still_life")*(metadata!$I$2:$I$187="high")*(RIGHT(metadata!$A$2:$A$187,2)="-1")) | D8: no (too few)
A9: other | B9: =SUMPRODUCT((metadata!$G$2:$G$187="other")*(RIGHT(metadata!$A$2:$A$187,2)="-1")) | C9: =SUMPRODUCT((metadata!$G$2:$G$187="other")*(metadata!$I$2:$I$187="high")*(RIGHT(metadata!$A$2:$A$187,2)="-1")) | D9: no (too few)
A10: total | B10: =SUM(B4:B9) | C10: =SUM(C4:C9)
A12: medium | B12: artworks | C12: high confidence | D12: used in experiments
A13: painting | B13: =SUMPRODUCT((metadata!$H$2:$H$187="painting")*(RIGHT(metadata!$A$2:$A$187,2)="-1")) | C13: =SUMPRODUCT((metadata!$H$2:$H$187="painting")*(metadata!$I$2:$I$187="high")*(RIGHT(metadata!$A$2:$A$187,2)="-1")) | D13: yes
A14: work_on_paper | B14: =SUMPRODUCT((metadata!$H$2:$H$187="work_on_paper")*(RIGHT(metadata!$A$2:$A$187,2)="-1")) | C14: =SUMPRODUCT((metadata!$H$2:$H$187="work_on_paper")*(metadata!$I$2:$I$187="high")*(RIGHT(metadata!$A$2:$A$187,2)="-1")) | D14: yes
A15: mixed_media | B15: =SUMPRODUCT((metadata!$H$2:$H$187="mixed_media")*(RIGHT(metadata!$A$2:$A$187,2)="-1")) | C15: =SUMPRODUCT((metadata!$H$2:$H$187="mixed_media")*(metadata!$I$2:$I$187="high")*(RIGHT(metadata!$A$2:$A$187,2)="-1")) | D15: no (too few)
A16: total | B16: =SUM(B13:B15) | C16: =SUM(C13:C15)
A18: photos in folder (JPG) | B18: =COUNTA(metadata!A2:A187)
A19: photos excluded | B19: =COUNTIF(metadata!A2:A187,"X-*")
A20: unique artworks | B20: =COUNTIF(metadata!A2:A187,"*-1")

Sheet label_guide
A1: Field | B1: Rule
A2: image_id | B2: A###-n = artwork number (in order photographed) + photo number of that artwork. X-### = excluded photo (### = capture order).
A3: artwork_id | B3: Same physical artwork = same ID. Always split train/test by this column, never by image.
A4: portrait | B4: One or two people where the face or upper body is the main subject (incl. equestrian portraits).
A5: landscape | B5: Outdoor scenery: nature, village, cityscape, seascape. Small figures allowed if the place dominates.
A6: figurative | B6: People, animals or scenes that are not a portrait: groups, full-body figures, nudes, religious and history scenes.
A7: abstract | B7: No clearly recognisable subject. Semi-abstract works are abstract with label_confidence = low.
A8: still_life / other | B8: Arranged objects or flowers / interiors and decorative designs. Too few artworks, not used.
A9: painting | B9: Oil or acrylic on canvas or board, usually without glass.
A10: work_on_paper | B10: Drawing, pastel, watercolour, print, lithograph, etching, poster. Usually behind glass with a mat.
A11: mixed_media | B11: Collage or assemblage. Too few, not used.
A12: label_confidence | B12: low = the genre or medium could reasonably be argued differently. Report results with and without these.
... A15: Not included | B15: 1 HEIC photo (Baratashvili, Shatili, 2015) was skipped as requested.
